Workbook
Name Slicer_Gender: #N/A
Name Slicer_Gender1: #N/A
Name Slicer_Months__Hiredate: #N/A

Sheet EMPLOYEE DASHBOARD
T2: EMPLOYEE DATA ANALYSIS
H27: Avg FAvg Female Salary $59,446 36% of workforceemale Salary $59,446 36% of workforce

Sheet STAFF
A1: Employee_ID | B1: First Name | C1: Last Name | D1: Gender | E1: State | F1: City | G1: Education Level | H1: Birthdate | I1: Hiredate | J1: Termdate | K1: Department | L1: Job Title | M1: Salary | N1: Atrrition status | O1: Performance Rating
A2: 00-10001272 | B2: Samuel | C2: Burgess | D2: Female | E2: West Virginia | F2: Huntington | G2: Bachelor | H2: 27405 | I2: 43403 | J2: N/A | K2: Customer Service | L2: Help Desk Technician | M2: 66787 | N2: =IF(J2="","Active","Terminated") -> Terminated | O2: Satisfactory
A3: 00-10006914 | B3: Ethan | C3: Case | D3: Male | E3: Michigan | F3: Detroit | G3: High School | H3: 29488 | I3: 44846 | J3: N/A | K3: Operations | L3: Inventory Specialist | M3: 63874 | N3: =IF(J3="","Active","Terminated") -> Terminated | O3: Needs Improvement
A4: 00-10008169 | B4: Barbara | C4: Blair | D4: Male | E4: Michigan | F4: Warren | G4: Bachelor | H4: 21759 | I4: 44888 | J4: N/A | K4: Operations | L4: Operations Analyst | M4: 88579 | N4: =IF(J4="","Active","Terminated") -> Terminated | O4: Good
A5: 00-10012470 | B5: Amy | C5: Davidson | D5: Female | E5: Michigan | F5: Grand Rapids | G5: Bachelor | H5: 32562 | I5: 43753 | J5: N/A | K5: Finance | L5: Accountant | M5: 62543 | N5: =IF(J5="","Active","Terminated") -> Terminated | O5: Good
A6: 00-10017850 | B6: Ricky | C6: Serrano | D6: Male | E6: New York | F6: New York City | G6: Bachelor | H6: 36787 | I6: 42650 | J6: N/A | K6: Sales | L6: Sales Specialist | M6: 92123 | N6: =IF(J6="","Active","Terminated") -> Terminated | O6: Good
A7: 00-10033114 | B7: Kathryn | C7: Scott | D7: Male | E7: New York | F7: New York City | G7: Bachelor | H7: 37077 | I7: 42990 | J7: N/A | K7: Operations | L7: Logistics Coordinator | M7: 64807 | N7: =IF(J7="","Active","Terminated") -> Terminated | O7: Good
A8: 00-10047461 | B8: Steven | C8: Armstrong | D8: Female | E8: Illinois | F8: Naperville | G8: Bachelor | H8: 33952 | I8: 42590 | J8: N/A | K8: Finance | L8: Accountant | M8: 70778 | N8: =IF(J8="","Active","Terminated") -> Terminated | O8: Satisfactory
A9: 00-10076576 | B9: Erica | C9: Kelly | D9: Male | E9: New York | F9: Buffalo | G9: Bachelor | H9: 36317 | I9: 43833 | J9: N/A | K9: Operations | L9: Inventory Specialist | M9: 63824 | N9: =IF(J9="","Active","Terminated") -> Terminated | O9: Excellent
A10: 00-10076959 | B10: Mark | C10: Stewart | D10: Male | E10: New York | F10: Buffalo | G10: Bachelor | H10: 23131 | I10: 42825 | J10: N/A | K10: Marketing | L10: Marketing Coordinator | M10: 76850 | N10: =IF(J10="","Active","Terminated") -> Terminated | O10: Satisfactory
A11: 00-10080009 | B11: Gabrielle | C11: Crane | D11: Female | E11: New York | F11: Buffalo | G11: Bachelor | H11: 28399 | I11: 44935 | J11: N/A | K11: Sales | L11: Sales Representative | M11: 59328 | N11: =IF(J11="","Active","Terminated") -> Terminated | O11: Good
A12: 00-10113173 | B12: Carol | C12: Smith | D12: Female | E12: Michigan | F12: Detroit | G12: High School | H12: 31919 | I12: 44764 | J12: N/A | K12: Marketing | L12: Content Creator | M12: 60340 | N12: =IF(J12="","Active","Terminated") -> Terminated | O12: Satisfactory
A13: 00-10113880 | B13: Brad | C13: Hobbs | D13: Male | E13: New York | F13: Buffalo | G13: High School | H13: 31651 | I13: 42815 | J13: N/A | K13: Marketing | L13: Content Creator | M13: 54733 | N13: =IF(J13="","Active","Terminated") -> Terminated | O13: Good
... A22: 00-10202363 | B22: Michelle | C22: Lang | D22: Female | E22: New York | F22: New York City | G22: Bachelor | H22: 35150 | I22: 44672 | J22: N/A | K22: Sales | L22: Sales Representative | M22: 52278 | N22: =IF(J22="","Active","Terminated") -> Terminated | O22: Satisfactory
A23: 00-10209961 | B23: Daniel | C23: Graham | D23: Male | E23: New York | F23: New York City | G23: Bachelor | H23: 32658 | I23: 44352 | J23: 44532 | K23: Sales | L23: Sales Representative | M23: 64892 | N23: =IF(J23="","Active","Terminated") -> Terminated | O23: Good
A24: 00-10213612 | B24: Gabriel | C24: Harris | D24: Female | E24: New York | F24: New York City | G24: Bachelor | H24: 27813 | I24: 44477 | J24: N/A | K24: Operations | L24: Operations Analyst | M24: 60624 | N24: =IF(J24="","Active","Terminated") -> Terminated | O24: Satisfactory
A25: 00-10225283 | B25: Ryan | C25: Long | D25: Female | E25: New York | F25: Rochester | G25: High School | H25: 26606 | I25: 43115 | J25: N/A | K25: Operations | L25: Inventory Specialist | M25: 59233 | N25: =IF(J25="","Active","Terminated") -> Terminated | O25: Satisfactory
A26: 00-10256489 | B26: Sue | C26: Howe | D26: Female | E26: New York | F26: Buffalo | G26: Bachelor | H26: 29633 | I26: 45418 | J26: N/A | K26: Sales | L26: Sales Representative | M26: 68287 | N26: =IF(J26="","Active","Terminated") -> Terminated | O26: Satisfactory
A27: 00-10261534 | B27: Kevin | C27: Potter | D27: Female | E27: Ohio | F27: Cincinnati | G27: Bachelor | H27: 28211 | I27: 45467 | J27: N/A | K27: Operations | L27: Logistics Coordinator | M27: 62856 | N27: =IF(J27="","Active","Terminated") -> Terminated | O27: Good
A28: 00-10270663 | B28: William | C28: Wilson | D28: Female | E28: New York | F28: New York City | G28: Bachelor | H28: 30745 | I28: 42958 | J28: N/A | K28: Sales | L28: Sales Representative | M28: 57572 | N28: =IF(J28="","Active","Terminated") -> Terminated | O28: Excellent
A29: 00-10274812 | B29: Heather | C29: Madden | D29: Female | E29: New York | F29: Rochester | G29: Bachelor | H29: 26390 | I29: 44484 | J29: N/A | K29: Operations | L29: Inventory Specialist | M29: 67571 | N29: =IF(J29="","Active","Terminated") -> Terminated | O29: Good
A30: 00-10279945 | B30: Karen | C30: Stephens | D30: Female | E30: New York | F30: Rochester | G30: High School | H30: 22399 | I30: 42708 | J30: N/A | K30: HR | L30: Recruiter | M30: 70509 | N30: =IF(J30="","Active","Terminated") -> Terminated | O30: Satisfactory
A31: 00-10289289 | B31: Robert | C31: Shields | D31: Female | E31: New York | F31: New York City | G31: Bachelor | H31: 28700 | I31: 45313 | J31: 45493 | K31: Customer Service | L31: Help Desk Technician | M31: 61403 | N31: =IF(J31="","Active","Terminated") -> Terminated | O31: Good
A32: 00-10299883 | B32: Shawn | C32: Sanchez | D32: Male | E32: New York | F32: Rochester | G32: Bachelor | H32: 25711 | I32: 44686 | J32: N/A | K32: Marketing | L32: Marketing Coordinator | M32: 69918 | N32: =IF(J32="","Active","Terminated") -> Terminated | O32: Good
A33: 00-10302186 | B33: Amy | C33: Davis | D33: Female | E33: New York | F33: Buffalo | G33: High School | H33: 26766 | I33: 43181 | J33: N/A | K33: Operations | L33: Inventory Specialist | M33: 65488 | N33: =IF(J33="","Active","Terminated") -> Terminated | O33: Satisfactory
A34: 00-10308646 | B34: Kristy | C34: Wilson | D34: Female | E34: New York | F34: Rochester | G34: High School | H34: 32660 | I34: 42883 | J34: N/A | K34: Marketing | L34: Content Creator | M34: 59706 | N34: =IF(J34="","Active","Terminated") -> Terminated | O34: Satisfactory
A35: 00-10329821 | B35: Mercedes | C35: Patterson | D35: Male | E35: New York | F35: New York City | G35: Bachelor | H35: 36415 | I35: 44681 | J35: N/A | K35: Operations | L35: Inventory Specialist | M35: 57722 | N35: =IF(J35="","Active","Terminated") -> Terminated | O35: Good
A36: 00-10331931 | B36: Gabriella | C36: Abbott | D36: Male | E36: New York | F36: New York City | G36: PhD | H36: 32530 | I36: 42989 | J36: 43168 | K36: Sales | L36: Sales Specialist | M36: 78790 | N36: =IF(J36="","Active","Terminated") -> Terminated | O36: Excellent
A37: 00-10332878 | B37: William | C37: Potter | D37: Female | E37: Virginia | F37: Norfolk | G37: Bachelor | H37: 36767 | I37: 45585 | J37: N/A | K37: Operations | L37: Logistics Coordinator | M37: 55750 | N37: =IF(J37="","Active","Terminated") -> Terminated | O37: Good
A38: 00-10333912 | B38: Angela | C38: Perry | D38: Male | E38: Illinois | F38: Naperville | G38: Bachelor | H38: 26067 | I38: 43437 | J38: N/A | K38: Operations | L38: Logistics Coordinator | M38: 62346 | N38: =IF(J38="","Active","Terminated") -> Terminated | O38: Satisfactory
A39: 00-10338423 | B39: Amanda | C39: Bradley | D39: Male | E39: West Virginia | F39: Charleston | G39: PhD | H39: 35327 | I39: 45168 | J39: N/A | K39: Sales | L39: Sales Specialist | M39: 78128 | N39: =IF(J39="","Active","Terminated") -> Terminated | O39: Good
A40: 00-10339260 | B40: Diana | C40: Jones | D40: Female | E40: New York | F40: Rochester | G40: Bachelor | H40: 26885 | I40: 43815 | J40: N/A | K40: Marketing | L40: SEO Specialist | M40: 61326 | N40: =IF(J40="","Active","Terminated") -> Terminated | O40: Good
A41: 00-10355692 | B41: Samuel | C41: Ayala | D41: Female | E41: New York | F41: Buffalo | G41: High School | H41: 22740 | I41: 42301 | J41: N/A | K41: Operations | L41: Inventory Specialist | M41: 56998 | N41: =IF(J41="","Active","Terminated") -> Terminated | O41: Excellent
A42: 00-10358749 | B42: Kimberly | C42: Mercado | D42: Female | E42: New York | F42: New York City | G42: High School | H42: 28585 | I42: 45246 | J42: N/A | K42: Marketing | L42: Content Creator | M42: 59294 | N42: =IF(J42="","Active","Terminated") -> Terminated | O42: Satisfactory
A43: 00-10392185 | B43: Sherry | C43: Carpenter | D43: Male | E43: North Carolina | F43: Raleigh | G43: High School | H43: 28486 | I43: 42438 | J43: N/A | K43: Customer Service | L43: Customer Service Representative | M43: 59847 | N43: =IF(J43="","Active","Terminated") -> Terminated | O43: Needs Improvement
A44: 00-10403216 | B44: Aaron | C44: Horton | D44: Female | E44: New York | F44: Rochester | G44: High School | H44: 34594 | I44: 43098 | J44: N/A | K44: Customer Service | L44: Support Specialist | M44: 60852 | N44: =IF(J44="","Active","Terminated") -> Terminated | O44: Satisfactory
A45: 00-10404729 | B45: John | C45: Grimes | D45: Female | E45: Virginia | F45: Virginia Beach | G45: Bachelor | H45: 29781 | I45: 44624 | J45: 44804 | K45: Customer Service | L45: Help Desk Technician | M45: 58407 | N45: =IF(J45="","Active","Terminated") -> Terminated | O45: Good
A46: 00-10409797 | B46: Gloria | C46: Hale | D46: Male | E46: Michigan | F46: Grand Rapids | G46: High School | H46: 35565 | I46: 43455 | J46: N/A | K46: Customer Service | L46: Help Desk Technician | M46: 57046 | N46: =IF(J46="","Active","Terminated") -> Terminated | O46: Needs Improvement
A47: 00-10412827 | B47: Savannah | C47: Howard | D47: Male | E47: North Carolina | F47: Raleigh | G47: High School | H47: 30977 | I47: 43730 | J47: N/A | K47: Operations | L47: Inventory Specialist | M47: 63356 | N47: =IF(J47="","Active","Terminated") -> Terminated | O47: Satisfactory
A48: 00-10432769 | B48: Robin | C48: Gutierrez | D48: Female | E48: New York | F48: Buffalo | G48: Bachelor | H48: 33867 | I48: 43419 | J48: N/A | K48: Customer Service | L48: Customer Service Representative | M48: 60621 | N48: =IF(J48="","Active","Terminated") -> Terminated | O48: Satisfactory
...

Sheet COUNT IF,SUMIFS&AVG IFS
B1: Department | C1: HEAD COUNT | D1: TOTAL SALARY | E1: AVG SALARY
B2: Customer Service | C2: =COUNTIF(STAFF!K:K,B2) -> 1673 | D2: =SUMIF(STAFF!K:K,B2,STAFF!M:M) -> 110146520 | E2: =AVERAGEIF(STAFF!K:K,B2,STAFF!M:M) -> 65837.729
B3: Operations | C3: =COUNTIF(STAFF!K:K,B3) -> 2718 | D3: =SUMIF(STAFF!K:K,B3,STAFF!M:M) -> 177757880 | E3: =AVERAGEIF(STAFF!K:K,B3,STAFF!M:M) -> 65400.25
B4: Finance | C4: =COUNTIF(STAFF!K:K,B4) -> 452 | D4: =SUMIF(STAFF!K:K,B4,STAFF!M:M) -> 34555917 | E4: =AVERAGEIF(STAFF!K:K,B4,STAFF!M:M) -> 76451.144
B5: Sales | C5: =COUNTIF(STAFF!K:K,B5) -> 1835 | D5: =SUMIF(STAFF!K:K,B5,STAFF!M:M) -> 139836079 | E5: =AVERAGEIF(STAFF!K:K,B5,STAFF!M:M) -> 76204.948
B6: Marketing | C6: =COUNTIF(STAFF!K:K,B6) -> 718 | D6: =SUMIF(STAFF!K:K,B6,STAFF!M:M) -> 48579179 | E6: =AVERAGEIF(STAFF!K:K,B6,STAFF!M:M) -> 67659.024
B7: HR | C7: =COUNTIF(STAFF!K:K,B7) -> 172 | D7: =SUMIF(STAFF!K:K,B7,STAFF!M:M) -> 11032946 | E7: =AVERAGEIF(STAFF!K:K,B7,STAFF!M:M) -> 64145.035
B8: IT | C8: =COUNTIF(STAFF!K:K,B8) -> 1382 | D8: =SUMIF(STAFF!K:K,B8,STAFF!M:M) -> 113221190 | E8: =AVERAGEIF(STAFF!K:K,B8,STAFF!M:M) -> 81925.608

Sheet FILTER FOR>120000,FEMALE 
F1: 120000
B3: {=_xlfn._xlws.FILTER(STAFF!A:M,STAFF!M:M>F1)} -> Employee_ID | C3: First Name | D3: Last Name | E3: Gender | F3: State | G3: City | H3: Education Level | I3: Birthdate | J3: Hiredate | K3: Termdate | L3: Department | M3: Job Title | N3: Salary | Q3: {=_xlfn._xlws.FILTER(STAFF!A:M,(STAFF!D:D="Female")*(STAFF!M:M>F1))} -> 00-11145938 | R3: Holly | S3: Gray | T3: Female | U3: New York | V3: New York City | W3: Master | X3: 36084 | Y3: 42983 | Z3: N/A | AA3: IT | AB3: IT Manager | AC3: 133425
B4: 00-10954878 | C4: Anita | D4: Wagner | E4: Male | F4: New York | G4: Rochester | H4: Master | I4: 37704 | J4: 44376 | K4: N/A | L4: IT | M4: IT Manager | N4: 121086 | Q4: 00-15537346 | R4: Jose | S4: Smith | T4: Female | U4: New York | V4: Buffalo | W4: PhD | X4: 22499 | Y4: 44869 | Z4: N/A | AA4: Finance | AB4: Finance Manager | AC4: 141543
B5: 00-11145938 | C5: Holly | D5: Gray | E5: Female | F5: New York | G5: New York City | H5: Master | I5: 36084 | J5: 42983 | K5: N/A | L5: IT | M5: IT Manager | N5: 133425 | Q5: 00-17850078 | R5: Dawn | S5: Hernandez | T5: Female | U5: New York | V5: Rochester | W5: Master | X5: 26012 | Y5: 43103 | Z5: N/A | AA5: Sales | AB5: Sales Manager | AC5: 125480
B6: 00-12738346 | C6: Kristen | D6: Green | E6: Male | F6: New York | G6: Rochester | H6: PhD | I6: 23310 | J6: 44806 | K6: N/A | L6: IT | M6: IT Manager | N6: 125068 | Q6: 00-23430634 | R6: Vincent | S6: Ross | T6: Female | U6: New York | V6: Rochester | W6: PhD | X6: 34332 | Y6: 43122 | Z6: N/A | AA6: Sales | AB6: Sales Manager | AC6: 133039
B7: 00-14237322 | C7: Kenneth | D7: Griffin | E7: Male | F7: New York | G7: New York City | H7: Master | I7: 32976 | J7: 44109 | K7: 44289 | L7: IT | M7: IT Manager | N7: 131494 | Q7: 00-30370571 | R7: Rebecca | S7: Estes | T7: Female | U7: Michigan | V7: Grand Rapids | W7: PhD | X7: 27872 | Y7: 45108 | Z7: N/A | AA7: Sales | AB7: Sales Manager | AC7: 127318
B8: 00-15537346 | C8: Jose | D8: Smith | E8: Female | F8: New York | G8: Buffalo | H8: PhD | I8: 22499 | J8: 44869 | K8: N/A | L8: Finance | M8: Finance Manager | N8: 141543 | Q8: 00-34077528 | R8: Gregory | S8: Wood | T8: Female | U8: New York | V8: Rochester | W8: Master | X8: 31675 | Y8: 43007 | Z8: N/A | AA8: Finance | AB8: Finance Manager | AC8: 132723
B9: 00-17850078 | C9: Dawn | D9: Hernandez | E9: Female | F9: New York | G9: Rochester | H9: Master | I9: 26012 | J9: 43103 | K9: N/A | L9: Sales | M9: Sales Manager | N9: 125480 | Q9: 00-42521351 | R9: Theresa | S9: Galloway | T9: Female | U9: New York | V9: Rochester | W9: PhD | X9: 21954 | Y9: 44087 | Z9: N/A | AA9: Sales | AB9: Sales Manager | AC9: 122906
B10: 00-18045780 | C10: Rodney | D10: Mosley | E10: Male | F10: Michigan | G10: Detroit | H10: Bachelor | I10: 25428 | J10: 44981 | K10: N/A | L10: IT | M10: Software Developer | N10: 120359 | Q10: 00-44042835 | R10: Raymond | S10: Lopez | T10: Female | U10: New York | V10: Buffalo | W10: PhD | X10: 34275 | Y10: 43708 | Z10: N/A | AA10: IT | AB10: IT Manager | AC10: 133044
B11: 00-23430634 | C11: Vincent | D11: Ross | E11: Female | F11: New York | G11: Rochester | H11: PhD | I11: 34332 | J11: 43122 | K11: N/A | L11: Sales | M11: Sales Manager | N11: 133039 | Q11: 00-48990885 | R11: Michael | S11: Mathews | T11: Female | U11: West Virginia | V11: Huntington | W11: Master | X11: 33839 | Y11: 44785 | Z11: N/A | AA11: IT | AB11: IT Manager | AC11: 128150
B12: 00-30370571 | C12: Rebecca | D12: Estes | E12: Female | F12: Michigan | G12: Grand Rapids | H12: PhD | I12: 27872 | J12: 45108 | K12: N/A | L12: Sales | M12: Sales Manager | N12: 127318 | Q12: 00-49657541 | R12: Dustin | S12: Martin | T12: Female | U12: New York | V12: Buffalo | W12: Master | X12: 26594 | Y12: 43052 | Z12: N/A | AA12: Sales | AB12: Sales Manager | AC12: 125832
B13: 00-34077528 | C13: Gregory | D13: Wood | E13: Female | F13: New York | G13: Rochester | H13: Master | I13: 31675 | J13: 43007 | K13: N/A | L13: Finance | M13: Finance Manager | N13: 132723 | Q13: 00-56069176 | R13: Michelle | S13: Ayers | T13: Female | U13: New York | V13: Rochester | W13: PhD | X13: 26493 | Y13: 43142 | Z13: N/A | AA13: Sales | AB13: Sales Manager | AC13: 135055
B14: 00-36772387 | C14: Michelle | D14: Burton | E14: Male | F14: New York | G14: New York City | H14: PhD | I14: 28741 | J14: 42794 | K14: 43160 | L14: Finance | M14: Finance Manager | N14: 122140 | Q14: 00-57263919 | R14: Tracey | S14: Hopkins | T14: Female | U14: Pennsylvania | V14: Pittsburgh | W14: Master | X14: 32830 | Y14: 45621 | Z14: N/A | AA14: Sales | AB14: Sales Manager | AC14: 120572
B15: 00-42521351 | C15: Theresa | D15: Galloway | E15: Female | F15: New York | G15: Rochester | H15: PhD | I15: 21954 | J15: 44087 | K15: N/A | L15: Sales | M15: Sales Manager | N15: 122906 | Q15: 00-62430296 | R15: Jeffrey | S15: Vaughan | T15: Female | U15: Illinois | V15: Chicago | W15: PhD | X15: 22846 | Y15: 42728 | Z15: N/A | AA15: Sales | AB15: Sales Manager | AC15: 130513
B16: 00-44042835 | C16: Raymond | D16: Lopez | E16: Female | F16: New York | G16: Buffalo | H16: PhD | I16: 34275 | J16: 43708 | K16: N/A | L16: IT | M16: IT Manager | N16: 133044 | Q16: 00-67841075 | R16: Barbara | S16: Tran | T16: Female | U16: Michigan | V16: Warren | W16: Master | X16: 28159 | Y16: 42840 | Z16: N/A | AA16: Finance | AB16: Finance Manager | AC16: 134173
B17: 00-46072958 | C17: Stephanie | D17: Murray | E17: Male | F17: New York | G17: New York City | H17: PhD | I17: 34600 | J17: 44837 | K17: 45017 | L17: IT | M17: IT Manager | N17: 120635 | Q17: 00-71836850 | R17: Michael | S17: Brown | T17: Female | U17: North Carolina | V17: Charlotte | W17: Master | X17: 26067 | Y17: 45013 | Z17: N/A | AA17: IT | AB17: IT Manager | AC17: 132590
B18: 00-48990885 | C18: Michael | D18: Mathews | E18: Female | F18: West Virginia | G18: Huntington | H18: Master | I18: 33839 | J18: 44785 | K18: N/A | L18: IT | M18: IT Manager | N18: 128150 | Q18: 00-80276331 | R18: Kristina | S18: Gardner | T18: Female | U18: New York | V18: New York City | W18: PhD | X18: 33006 | Y18: 42805 | Z18: N/A | AA18: Finance | AB18: Finance Manager | AC18: 149377
B19: 00-49657541 | C19: Dustin | D19: Martin | E19: Female | F19: New York | G19: Buffalo | H19: Master | I19: 26594 | J19: 43052 | K19: N/A | L19: Sales | M19: Sales Manager | N19: 125832 | Q19: 00-84386123 | R19: Margaret | S19: Gill | T19: Female | U19: Pennsylvania | V19: Philadelphia | W19: Master | X19: 35076 | Y19: 42634 | Z19: 44049 | AA19: Sales | AB19: Sales Manager | AC19: 124824
B20: 00-56069176 | C20: Michelle | D20: Ayers | E20: Female | F20: New York | G20: Rochester | H20: PhD | I20: 26493 | J20: 43142 | K20: N/A | L20: Sales | M20: Sales Manager | N20: 135055 | Q20: 00-94437310 | R20: Andrew | S20: Garcia | T20: Female | U20: New York | V20: Buffalo | W20: PhD | X20: 22547 | Y20: 45509 | Z20: N/A | AA20: IT | AB20: IT Manager | AC20: 121860
B21: 00-57263919 | C21: Tracey | D21: Hopkins | E21: Female | F21: Pennsylvania | G21: Pittsburgh | H21: Master | I21: 32830 | J21: 45621 | K21: N/A | L21: Sales | M21: Sales Manager | N21: 120572
B22: 00-62430296 | C22: Jeffrey | D22: Vaughan | E22: Female | F22: Illinois | G22: Chicago | H22: PhD | I22: 22846 | J22: 42728 | K22: N/A | L22: Sales | M22: Sales Manager | N22: 130513
B23: 00-67841075 | C23: Barbara | D23: Tran | E23: Female | F23: Michigan | G23: Warren | H23: Master | I23: 28159 | J23: 42840 | K23: N/A | L23: Finance | M23: Finance Manager | N23: 134173
B24: 00-70313693 | C24: Luis | D24: Rogers | E24: Male | F24: New York | G24: New York City | H24: PhD | I24: 25519 | J24: 43801 | K24: N/A | L24: IT | M24: IT Manager | N24: 128906
B25: 00-71836850 | C25: Michael | D25: Brown | E25: Female | F25: North Carolina | G25: Charlotte | H25: Master | I25: 26067 | J25: 45013 | K25: N/A | L25: IT | M25: IT Manager | N25: 132590
B26: 00-80276331 | C26: Kristina | D26: Gardner | E26: Female | F26: New York | G26: New York City | H26: PhD | I26: 33006 | J26: 42805 | K26: N/A | L26: Finance | M26: Finance Manager | N26: 149377
B27: 00-84386123 | C27: Margaret | D27: Gill | E27: Female | F27: Pennsylvania | G27: Philadelphia | H27: Master | I27: 35076 | J27: 42634 | K27: 44049 | L27: Sales | M27: Sales Manager | N27: 124824
B28: 00-94437310 | C28: Andrew | D28: Garcia | E28: Female | F28: New York | G28: Buffalo | H28: PhD | I28: 22547 | J28: 45509 | K28: N/A | L28: IT | M28: IT Manager | N28: 121860
B29: 00-99031467 | C29: Lisa | D29: Rodriguez | E29: Male | F29: New York | G29: Rochester | H29: PhD | I29: 22995 | J29: 45462 | K29: N/A | L29: IT | M29: IT Manager | N29: 131830

Sheet MIN,MAX SALARY
C2: ALL EMPLYS | D2: Male | E2: Female
A3: LOWEST SALARY | C3: =MIN(STAFF!M:M) -> 51835 | D3: =_xlfn.MINIFS(STAFF!M2:M19000,STAFF!D2:D19000,"Male") -> 52612 | E3: =_xlfn.MINIFS(STAFF!M2:M19000,STAFF!D2:D19000,"Female") -> 51835
A4: HIGHEST SALARY | C4: =MAX(STAFF!M:M) -> 149377 | D4: =_xlfn.MAXIFS(STAFF!M2:M19000,STAFF!D2:D19000,"Male") -> 131830 | E4: =_xlfn.MAXIFS(STAFF!M2:M19000,STAFF!D2:D19000,"Female") -> 149377
A5: TOP 5 SLARIES | C5: =LARGE(STAFF!M:M,I5) -> 149377 | D5: {=LARGE(IF(STAFF!D2:D19000="Male",STAFF!M2:M19000),1)} -> 131830 | E5: {=LARGE(IF(STAFF!D2:D19000="Female",STAFF!M2:M19000),J5)} -> 149377 | I5: 1 | J5: 1 | K5: 1
C6: =LARGE(STAFF!M:M,I6) -> 141543 | D6: {=LARGE(IF(STAFF!D3:D19001="Male",STAFF!M3:M19001),1)} -> 131830 | E6: {=LARGE(IF(STAFF!D3:D19001="Female",STAFF!M3:M19001),J6)} -> 141543 | I6: 2 | J6: 2 | K6: 2
C7: =LARGE(STAFF!M:M,I7) -> 135055 | D7: {=LARGE(IF(STAFF!D4:D19002="Male",STAFF!M4:M19002),1)} -> 131830 | E7: {=LARGE(IF(STAFF!D4:D19002="Female",STAFF!M4:M19002),J7)} -> 135055 | I7: 3 | J7: 3 | K7: 3
C8: =LARGE(STAFF!M:M,I8) -> 134173 | D8: {=LARGE(IF(STAFF!D5:D19003="Male",STAFF!M5:M19003),1)} -> 131830 | E8: {=LARGE(IF(STAFF!D5:D19003="Female",STAFF!M5:M19003),J8)} -> 134173 | I8: 4 | J8: 4 | K8: 4
C9: =LARGE(STAFF!M:M,I9) -> 133425 | D9: {=LARGE(IF(STAFF!D6:D19004="Male",STAFF!M6:M19004),1)} -> 131830 | E9: {=LARGE(IF(STAFF!D6:D19004="Female",STAFF!M6:M19004),J9)} -> 133425 | I9: 5 | J9: 5 | K9: 5
A12: TOP 5 SALARIES | C12: =IFERROR(SMALL(STAFF!M:M,I5),0) -> 51835 | D12: {=IFERROR(SMALL(IF(STAFF!D:D="Male",STAFF!M:M),J5),0)} -> 52612 | E12: {=IFERROR(SMALL(IF(STAFF!D:D="Female",STAFF!M:M),K5),0)} -> 51835
A13: FROM LOWEST | C13: =IFERROR(SMALL(STAFF!M:M,I6),0) -> 51865 | D13: {=IFERROR(SMALL(IF(STAFF!D:D="Male",STAFF!M:M),J6),0)} -> 52642 | E13: {=IFERROR(SMALL(IF(STAFF!D:D="Female",STAFF!M:M),K6),0)} -> 51865
C14: =IFERROR(SMALL(STAFF!M:M,I7),0) -> 51887 | D14: {=IFERROR(SMALL(IF(STAFF!D:D="Male",STAFF!M:M),J7),0)} -> 52759 | E14: {=IFERROR(SMALL(IF(STAFF!D:D="Female",STAFF!M:M),K7),0)} -> 51887
C15: =IFERROR(SMALL(STAFF!M:M,I8),0) -> 51887 | D15: {=IFERROR(SMALL(IF(STAFF!D:D="Male",STAFF!M:M),J8),0)} -> 52836 | E15: {=IFERROR(SMALL(IF(STAFF!D:D="Female",STAFF!M:M),K8),0)} -> 51887
C16: =IFERROR(SMALL(STAFF!M:M,I9),0) -> 51919 | D16: {=IFERROR(SMALL(IF(STAFF!D:D="Male",STAFF!M:M),J9),0)} -> 52966 | E16: {=IFERROR(SMALL(IF(STAFF!D:D="Female",STAFF!M:M),K9),0)} -> 51919

Sheet COUNTA FOR DEPT
A1: List of all departments
A3: {=_xlfn.UNIQUE(STAFF!K2:K19000)} -> Customer Service | D3: COUNT | E3: =COUNTA(_xlfn.UNIQUE(STAFF!K2:K19000)) -> 8
A4: Operations
A5: Finance
A6: Sales
A7: Marketing
A8: HR
A9: IT
A10: 0

Sheet VLOOKUP,XLOOKUP
B2: Employee ID | C2: 00-10001272 | F2: With XLOOKUP
B5: First Name | C5: =VLOOKUP(C2,STAFF!A:M,2,FALSE) -> Samuel | F5: =_xlfn.XLOOKUP(C2,STAFF!A:A,STAFF!B:B,"Not Found") -> Samuel
B6: Last Name | C6: =VLOOKUP(C2,STAFF!A:M,3,FALSE) -> Burgess | F6: =_xlfn.XLOOKUP(C2,STAFF!A:A,STAFF!C:C) -> Burgess
B7: Department | C7: =VLOOKUP(C2,STAFF!A:M,11,FALSE) -> Customer Service | F7: =_xlfn.XLOOKUP(C2,STAFF!A:A,STAFF!K:K) -> Customer Service
B8: Salary | C8: =VLOOKUP(C2,STAFF!A:M,13,FALSE) -> 66787 | F8: =_xlfn.XLOOKUP(C2,STAFF!A:A,STAFF!M:M) -> 66787
I11: ENTIRE DATA
B13: LAST | C13: Perry | I13: {=_xlfn.XLOOKUP(C13,STAFF!C:C,STAFF!A:M,"NOT FOUND")} -> 00-10333912 | J13: Angela | K13: Perry | L13: Male | M13: Illinois | N13: Naperville | O13: Bachelor | P13: 26067 | Q13: 43437 | R13: N/A | S13: Operations | T13: Logistics Coordinator | U13: 62346
C14: =MATCH(C13,STAFF!C:C,0) -> 38
I15: {=TRANSPOSE(_xlfn.XLOOKUP(C13,STAFF!C:C,STAFF!A:M))} -> 00-10333912
I16: Angela
B17: Employee ID | C17: =INDEX(STAFF!A:A,MATCH(C13,STAFF!C:C,0)) -> 00-10333912 | F17: =_xlfn.XLOOKUP(C13,STAFF!C:C,STAFF!A:A,"NOT FOUND") -> 00-10333912 | I17: Perry
B18: Department | C18: =INDEX(STAFF!K:K,MATCH(C13,STAFF!C:C,0)) -> Operations | F18: =_xlfn.XLOOKUP(C13,STAFF!C:C,STAFF!K:K,"NOT FOUND") -> Operations | I18: Male
B19: Salary | C19: =INDEX(STAFF!M:M,MATCH(C13,STAFF!C:C,0)) -> 62346 | F19: =_xlfn.XLOOKUP(C13,STAFF!C:C,STAFF!M:M,"NOT FOUND") -> 62346 | I19: Illinois
I20: Naperville
I21: Bachelor
I22: 26067
I23: 43437
I24: N/A
I25: Operations
I26: Logistics Coordinator
I27: 62346

Sheet XLOOKUPWITH MAX
C2: One person | E2: {=_xlfn.XLOOKUP(MAX(STAFF!M:M),STAFF!M:M,STAFF!B:B & " "& STAFF!C:C)} -> Kristina Gardner
C6: All persons | E6: {=_xlfn._xlws.FILTER(STAFF!B:B,STAFF!M:M=MAX(STAFF!M:M))} -> Kristina

Sheet FILTER FOR MONTH MARCH
A1: Employee_ID | B1: First Name | C1: Last Name | D1: Gender | E1: State | F1: City | G1: Education Level | H1: Birthdate | I1: Hiredate | J1: Termdate | K1: Department | L1: Job Title | M1: Salary | N1: Atrrition status | O1: Performance Rating
A2: {=_xlfn._xlws.FILTER(STAFF!A2:O19000,MONTH(STAFF!I2:I19000)=3)} -> 00-10076959 | B2: Mark | C2: Stewart | D2: Male | E2: New York | F2: Buffalo | G2: Bachelor | H2: 23131 | I2: 42825 | J2: N/A | K2: Marketing | L2: Marketing Coordinator | M2: 76850 | N2: Terminated | O2: Satisfactory
A3: 00-10113880 | B3: Brad | C3: Hobbs | D3: Male | E3: New York | F3: Buffalo | G3: High School | H3: 31651 | I3: 42815 | J3: N/A | K3: Marketing | L3: Content Creator | M3: 54733 | N3: Terminated | O3: Good
A4: 00-10147197 | B4: Henry | C4: Mccarthy | D4: Female | E4: New York | F4: Buffalo | G4: Bachelor | H4: 30757 | I4: 44995 | J4: N/A | K4: Operations | L4: Operations Analyst | M4: 56478 | N4: Terminated | O4: Good
A5: 00-10195370 | B5: Daniel | C5: Maxwell | D5: Male | E5: Illinois | F5: Naperville | G5: High School | H5: 25817 | I5: 43180 | J5: N/A | K5: Customer Service | L5: Support Specialist | M5: 64056 | N5: Terminated | O5: Good
A6: 00-10302186 | B6: Amy | C6: Davis | D6: Female | E6: New York | F6: Buffalo | G6: High School | H6: 26766 | I6: 43181 | J6: N/A | K6: Operations | L6: Inventory Specialist | M6: 65488 | N6: Terminated | O6: Satisfactory
A7: 00-10392185 | B7: Sherry | C7: Carpenter | D7: Male | E7: North Carolina | F7: Raleigh | G7: High School | H7: 28486 | I7: 42438 | J7: N/A | K7: Customer Service | L7: Customer Service Representative | M7: 59847 | N7: Terminated | O7: Needs Improvement
A8: 00-10404729 | B8: John | C8: Grimes | D8: Female | E8: Virginia | F8: Virginia Beach | G8: Bachelor | H8: 29781 | I8: 44624 | J8: 44804 | K8: Customer Service | L8: Help Desk Technician | M8: 58407 | N8: Terminated | O8: Good
A9: 00-10470877 | B9: Paul | C9: Day | D9: Male | E9: New York | F9: Rochester | G9: Master | H9: 22624 | I9: 43178 | J9: N/A | K9: HR | L9: HR Coordinator | M9: 54969 | N9: Terminated | O9: Good
A10: 00-10617870 | B10: Erin | C10: Ramos | D10: Female | E10: New York | F10: Buffalo | G10: Bachelor | H10: 31413 | I10: 45370 | J10: N/A | K10: Operations | L10: Operations Manager | M10: 95684 | N10: Terminated | O10: Good
A11: 00-10667294 | B11: David | C11: Sims | D11: Male | E11: New York | F11: New York City | G11: Bachelor | H11: 26498 | I11: 42816 | J11: N/A | K11: Operations | L11: Logistics Coordinator | M11: 66996 | N11: Terminated | O11: Satisfactory
A12: 00-10753570 | B12: Carolyn | C12: Robinson | D12: Female | E12: New York | F12: New York City | G12: Bachelor | H12: 29386 | I12: 43912 | J12: N/A | K12: Customer Service | L12: Support Specialist | M12: 63693 | N12: Terminated | O12: Satisfactory
A13: 00-10959975 | B13: Lori | C13: Daniels | D13: Female | E13: Pennsylvania | F13: Philadelphia | G13: Bachelor | H13: 37328 | I13: 43170 | J13: N/A | K13: Sales | L13: Sales Representative | M13: 58267 | N13: Terminated | O13: Excellent
A14: 00-11031743 | B14: Robert | C14: Newton | D14: Male | E14: New York | F14: New York City | G14: Bachelor | H14: 32868 | I14: 42796 | J14: N/A | K14: Operations | L14: Logistics Coordinator | M14: 64797 | N14: Terminated | O14: Needs Improvement
A15: 00-11190605 | B15: Stephanie | C15: Gibbs | D15: Female | E15: New York | F15: Rochester | G15: Bachelor | H15: 37522 | I15: 43530 | J15: N/A | K15: HR | L15: Recruiter | M15: 69690 | N15: Terminated | O15: Good
A16: 00-11224073 | B16: Albert | C16: Palmer | D16: Male | E16: New York | F16: Buffalo | G16: High School | H16: 32050 | I16: 45352 | J16: N/A | K16: HR | L16: Recruiter | M16: 62801 | N16: Terminated | O16: Excellent
A17: 00-11292919 | B17: Karen | C17: Lamb | D17: Male | E17: Ohio | F17: Cincinnati | G17: Bachelor | H17: 32189 | I17: 43175 | J17: N/A | K17: Customer Service | L17: Support Specialist | M17: 70150 | N17: Terminated | O17: Good
A18: 00-11294689 | B18: Nicole | C18: Manning | D18: Male | E18: New York | F18: Rochester | G18: High School | H18: 23580 | I18: 42824 | J18: N/A | K18: IT | L18: IT Support Specialist | M18: 57322 | N18: Terminated | O18: Good
A19: 00-11306363 | B19: Matthew | C19: Castillo | D19: Female | E19: New York | F19: New York City | G19: Master | H19: 30028 | I19: 43903 | J19: N/A | K19: IT | L19: Software Developer | M19: 107398 | N19: Terminated | O19: Good
A20: 00-11458621 | B20: Donna | C20: Gomez | D20: Male | E20: Michigan | F20: Detroit | G20: Bachelor | H20: 26336 | I20: 43553 | J20: N/A | K20: Operations | L20: Operations Manager | M20: 105680 | N20: Terminated | O20: Satisfactory
... A24: 00-11967696 | B24: Craig | C24: Roth | D24: Male | E24: Illinois | F24: Chicago | G24: Master | H24: 35442 | I24: 42439 | J24: N/A | K24: IT | L24: System Administrator | M24: 72088 | N24: Terminated | O24: Good
A25: 00-12058055 | B25: Bryan | C25: Taylor | D25: Female | E25: New York | F25: New York City | G25: Bachelor | H25: 27556 | I25: 42816 | J25: 43578 | K25: Operations | L25: Logistics Coordinator | M25: 55963 | N25: Terminated | O25: Needs Improvement
A26: 00-12247218 | B26: Adam | C26: Caldwell | D26: Male | E26: North Carolina | F26: Charlotte | G26: Master | H26: 28696 | I26: 42824 | J26: N/A | K26: Sales | L26: Sales Consultant | M26: 77326 | N26: Terminated | O26: Good
A27: 00-12328554 | B27: Erin | C27: Jones | D27: Female | E27: New York | F27: New York City | G27: Master | H27: 33082 | I27: 43190 | J27: N/A | K27: IT | L27: Software Developer | M27: 97588 | N27: Terminated | O27: Satisfactory
A28: 00-12354860 | B28: Katherine | C28: Fowler | D28: Male | E28: New York | F28: New York City | G28: High School | H28: 29965 | I28: 45008 | J28: N/A | K28: Customer Service | L28: Support Specialist | M28: 59438 | N28: Terminated | O28: Satisfactory
A29: 00-12371679 | B29: Cassandra | C29: Simmons | D29: Female | E29: New York | F29: Rochester | G29: Bachelor | H29: 33011 | I29: 45361 | J29: N/A | K29: Sales | L29: Sales Representative | M29: 66440 | N29: Terminated | O29: Excellent
A30: 00-12425579 | B30: George | C30: Sharp | D30: Female | E30: New York | F30: Buffalo | G30: High School | H30: 27389 | I30: 42088 | J30: N/A | K30: Customer Service | L30: Customer Service Representative | M30: 62804 | N30: Terminated | O30: Needs Improvement
A31: 00-12621771 | B31: Timothy | C31: Carpenter | D31: Female | E31: New York | F31: Buffalo | G31: Bachelor | H31: 31811 | I31: 45003 | J31: N/A | K31: Operations | L31: Operations Analyst | M31: 68687 | N31: Terminated | O31: Good
A32: 00-12632034 | B32: Mckenzie | C32: Smith | D32: Female | E32: Pennsylvania | F32: Allentown | G32: PhD | H32: 29644 | I32: 44636 | J32: N/A | K32: Sales | L32: Sales Consultant | M32: 82614 | N32: Terminated | O32: Good
A33: 00-12655477 | B33: Ashley | C33: Alexander | D33: Male | E33: New York | F33: Buffalo | G33: High School | H33: 30562 | I33: 43528 | J33: N/A | K33: Customer Service | L33: Support Specialist | M33: 68154 | N33: Terminated | O33: Good
A34: 00-12795332 | B34: Brian | C34: Grimes | D34: Female | E34: New York | F34: Buffalo | G34: Bachelor | H34: 31219 | I34: 42805 | J34: N/A | K34: Operations | L34: Logistics Coordinator | M34: 62116 | N34: Terminated | O34: Good
A35: 00-12857448 | B35: John | C35: Jacobson | D35: Male | E35: New York | F35: Buffalo | G35: High School | H35: 29130 | I35: 43901 | J35: N/A | K35: Operations | L35: Inventory Specialist | M35: 58008 | N35: Terminated | O35: Needs Improvement
A36: 00-12947014 | B36: David | C36: Frederick | D36: Female | E36: New York | F36: Rochester | G36: Master | H36: 35459 | I36: 43529 | J36: N/A | K36: Operations | L36: Operations Analyst | M36: 81438 | N36: Terminated | O36: Excellent
A37: 00-13235892 | B37: Richard | C37: Montgomery | D37: Male | E37: New York | F37: Rochester | G37: Bachelor | H37: 36834 | I37: 42802 | J37: N/A | K37: Customer Service | L37: Support Specialist | M37: 70659 | N37: Terminated | O37: Excellent
... A45: 00-14255661 | B45: James | C45: Hawkins | D45: Female | E45: New York | F45: Rochester | G45: Bachelor | H45: 36481 | I45: 42457 | J45: N/A | K45: Operations | L45: Logistics Coordinator | M45: 58009 | N45: Terminated | O45: Good
A46: 00-14416002 | B46: Stephen | C46: Scott | D46: Male | E46: Pennsylvania | F46: Pittsburgh | G46: Master | H46: 30628 | I46: 42808 | J46: 45225 | K46: Sales | L46: Sales Specialist | M46: 55995 | N46: Terminated | O46: Excellent
A47: 00-14535123 | B47: Katelyn | C47: Turner | D47: Female | E47: New York | F47: New York City | G47: Master | H47: 29451 | I47: 43912 | J47: N/A | K47: Sales | L47: Sales Consultant | M47: 103135 | N47: Terminated | O47: Good
A48: 00-14548283 | B48: Diana | C48: Simpson | D48: Female | E48: New York | F48: Rochester | G48: Bachelor | H48: 32129 | I48: 44634 | J48: N/A | K48: Operations | L48: Inventory Specialist | M48: 56474 | N48: Terminated | O48: Satisfactory
A49: 00-14840043 | B49: Brian | C49: Schneider | D49: Female | E49: New York | F49: New York City | G49: Bachelor | H49: 33709 | I49: 43161 | J49: N/A | K49: Customer Service | L49: Support Specialist | M49: 56253 | N49: Terminated | O49: Satisfactory
A50: 00-15307982 | B50: Robert | C50: Gutierrez | D50: Male | E50: New York | F50: New York City | G50: High School | H50: 33245 | I50: 42815 | J50: 43456 | K50: Operations | L50: Inventory Specialist | M50: 59202 | N50: Terminated | O50: Needs Improvement
...

Sheet FILTER FOR WEEKDAYS (MONDAY)
B1: Employee_ID | C1: First Name | D1: Last Name | E1: Gender | F1: State | G1: City | H1: Education Level | I1: Birthdate | J1: Hiredate | K1: Termdate | L1: Department | M1: Job Title | N1: Salary | O1: Atrrition status | P1: Performance Rating | R1: CHECK
B2: {=_xlfn._xlws.FILTER(STAFF!A2:O19000,(STAFF!D2:D19000="Female")*(WEEKDAY(STAFF!I2:I19000,2)=1))} -> 00-10047461 | C2: Steven | D2: Armstrong | E2: Female | F2: Illinois | G2: Naperville | H2: Bachelor | I2: 33952 | J2: 42590 | K2: N/A | L2: Finance | M2: Accountant | N2: 70778 | O2: Terminated | P2: Satisfactory | R2: =WEEKDAY(J3,2)=1 -> TRUE
B3: 00-10080009 | C3: Gabrielle | D3: Crane | E3: Female | F3: New York | G3: Buffalo | H3: Bachelor | I3: 28399 | J3: 44935 | K3: N/A | L3: Sales | M3: Sales Representative | N3: 59328 | O3: Terminated | P3: Good | R3: =WEEKDAY(J4,2)=1 -> TRUE
B4: 00-10122731 | C4: Travis | D4: Aguirre | E4: Female | F4: Ohio | G4: Cleveland | H4: Master | I4: 25354 | J4: 42422 | K4: N/A | L4: Operations | M4: Operations Analyst | N4: 79145 | O4: Terminated | P4: Excellent | R4: =WEEKDAY(J5,2)=1 -> TRUE
B5: 00-10225283 | C5: Ryan | D5: Long | E5: Female | F5: New York | G5: Rochester | H5: High School | I5: 26606 | J5: 43115 | K5: N/A | L5: Operations | M5: Inventory Specialist | N5: 59233 | O5: Terminated | P5: Satisfactory | R5: =WEEKDAY(J6,2)=1 -> TRUE
B6: 00-10256489 | C6: Sue | D6: Howe | E6: Female | F6: New York | G6: Buffalo | H6: Bachelor | I6: 29633 | J6: 45418 | K6: N/A | L6: Sales | M6: Sales Representative | N6: 68287 | O6: Terminated | P6: Satisfactory | R6: =WEEKDAY(J7,2)=1 -> TRUE
B7: 00-10261534 | C7: Kevin | D7: Potter | E7: Female | F7: Ohio | G7: Cincinnati | H7: Bachelor | I7: 28211 | J7: 45467 | K7: N/A | L7: Operations | M7: Logistics Coordinator | N7: 62856 | O7: Terminated | P7: Good | R7: =WEEKDAY(J8,2)=1 -> TRUE
B8: 00-10289289 | C8: Robert | D8: Shields | E8: Female | F8: New York | G8: New York City | H8: Bachelor | I8: 28700 | J8: 45313 | K8: 45493 | L8: Customer Service | M8: Help Desk Technician | N8: 61403 | O8: Terminated | P8: Good | R8: =WEEKDAY(J9,2)=1 -> TRUE
B9: 00-10339260 | C9: Diana | D9: Jones | E9: Female | F9: New York | G9: Rochester | H9: Bachelor | I9: 26885 | J9: 43815 | K9: N/A | L9: Marketing | M9: SEO Specialist | N9: 61326 | O9: Terminated | P9: Good | R9: =WEEKDAY(J10,2)=1 -> TRUE
B10: 00-10446705 | C10: Michelle | D10: Johnson | E10: Female | F10: New York | G10: Buffalo | H10: Bachelor | I10: 37372 | J10: 45446 | K10: N/A | L10: Customer Service | M10: Support Specialist | N10: 54933 | O10: Terminated | P10: Good | R10: =WEEKDAY(J11,2)=1 -> TRUE
B11: 00-10457051 | C11: Christopher | D11: Pitts | E11: Female | F11: New York | G11: Buffalo | H11: Bachelor | I11: 23453 | J11: 42380 | K11: N/A | L11: Sales | M11: Sales Representative | N11: 61979 | O11: Terminated | P11: Good | R11: =WEEKDAY(J12,2)=1 -> TRUE
B12: 00-10466177 | C12: Joseph | D12: Diaz | E12: Female | F12: Michigan | G12: Warren | H12: Bachelor | I12: 33369 | J12: 44718 | K12: 44898 | L12: Finance | M12: Accountant | N12: 53179 | O12: Terminated | P12: Satisfactory | R12: =WEEKDAY(J13,2)=1 -> TRUE
B13: 00-10691813 | C13: Robert | D13: Woodard | E13: Female | F13: New York | G13: Buffalo | H13: High School | I13: 23506 | J13: 43374 | K13: N/A | L13: Customer Service | M13: Support Specialist | N13: 61344 | O13: Terminated | P13: Satisfactory | R13: =WEEKDAY(J14,2)=1 -> TRUE
B14: 00-10865811 | C14: Debbie | D14: Klein | E14: Female | F14: New York | G14: Rochester | H14: Bachelor | I14: 25616 | J14: 45145 | K14: N/A | L14: Marketing | M14: Content Creator | N14: 57329 | O14: Terminated | P14: Satisfactory | R14: =WEEKDAY(J15,2)=1 -> TRUE
B15: 00-10884169 | C15: Elizabeth | D15: Spence | E15: Female | F15: New York | G15: New York City | H15: Bachelor | I15: 24809 | J15: 42793 | K15: N/A | L15: Sales | M15: Sales Representative | N15: 69161 | O15: Terminated | P15: Good | R15: =WEEKDAY(J16,2)=1 -> TRUE
B16: 00-11020743 | C16: Elizabeth | D16: Wright | E16: Female | F16: Michigan | G16: Warren | H16: Bachelor | I16: 36446 | J16: 45558 | K16: N/A | L16: Finance | M16: Accounts Payable Specialist | N16: 59278 | O16: Terminated | P16: Needs Improvement | R16: =WEEKDAY(J17,2)=1 -> TRUE
B17: 00-11116303 | C17: Danny | D17: Reed | E17: Female | F17: New York | G17: New York City | H17: PhD | I17: 29458 | J17: 44655 | K17: N/A | L17: IT | M17: IT Manager | N17: 113352 | O17: Terminated | P17: Excellent | R17: =WEEKDAY(J18,2)=1 -> TRUE
B18: 00-11162685 | C18: Catherine | D18: Baker | E18: Female | F18: Ohio | G18: Columbus | H18: Bachelor | I18: 31897 | J18: 42996 | K18: N/A | L18: Marketing | M18: Marketing Coordinator | N18: 67298 | O18: Terminated | P18: Satisfactory | R18: =WEEKDAY(J19,2)=1 -> TRUE
B19: 00-11385159 | C19: Lori | D19: Davis | E19: Female | F19: New York | G19: Buffalo | H19: Bachelor | I19: 32697 | J19: 43703 | K19: N/A | L19: Customer Service | M19: Help Desk Technician | N19: 69757 | O19: Terminated | P19: Good | R19: =WEEKDAY(J20,2)=1 -> TRUE
B20: 00-11558972 | C20: Anna | D20: Brown | E20: Female | F20: Ohio | G20: Cleveland | H20: PhD | I20: 27116 | J20: 42933 | K20: N/A | L20: Sales | M20: Sales Specialist | N20: 95430 | O20: Terminated | P20: Satisfactory | R20: =WEEKDAY(J21,2)=1 -> TRUE
B21: 00-11760963 | C21: Erica | D21: Rangel | E21: Female | F21: New York | G21: New York City | H21: Bachelor | I21: 29612 | J21: 42779 | K21: N/A | L21: Finance | M21: Financial Analyst | N21: 85672 | O21: Terminated | P21: Good | R21: =WEEKDAY(J22,2)=1 -> TRUE
B22: 00-12193574 | C22: Elizabeth | D22: King | E22: Female | F22: New York | G22: Rochester | H22: Bachelor | I22: 24231 | J22: 43969 | K22: N/A | L22: Finance | M22: Accountant | N22: 87983 | O22: Terminated | P22: Needs Improvement | R22: =WEEKDAY(J23,2)=1 -> TRUE
B23: 00-12423190 | C23: Lisa | D23: Erickson | E23: Female | F23: New York | G23: New York City | H23: Bachelor | I23: 36727 | J23: 44389 | K23: N/A | L23: Finance | M23: Accountant | N23: 75070 | O23: Terminated | P23: Satisfactory | R23: =WEEKDAY(J24,2)=1 -> TRUE
B24: 00-12641440 | C24: Dustin | D24: Nelson | E24: Female | F24: New York | G24: Buffalo | H24: Master | I24: 34240 | J24: 42541 | K24: N/A | L24: Operations | M24: Operations Analyst | N24: 82759 | O24: Terminated | P24: Good | R24: =WEEKDAY(J25,2)=1 -> TRUE
... B49: 00-16986408 | C49: Mary | D49: Mcpherson | E49: Female | F49: New York | G49: New York City | H49: Bachelor | I49: 36711 | J49: 42786 | K49: N/A | L49: Sales | M49: Sales Representative | N49: 63747 | O49: Terminated | P49: Good | R49: =WEEKDAY(J50,2)=1 -> TRUE
B50: 00-17195288 | C50: Curtis | D50: Barton | E50: Female | F50: New York | G50: New York City | H50: High School | I50: 32692 | J50: 43066 | K50: 43453 | L50: Marketing | M50: Content Creator | N50: 53525 | O50: Terminated | P50: Needs Improvement | R50: =WEEKDAY(J51,2)=1 -> TRUE
B51: 00-17200210 | C51: John | D51: Edwards | E51: Female | F51: New York | G51: Rochester | H51: High School | I51: 32899 | J51: 42863 | K51: N/A | L51: IT | M51: IT Support Specialist | N51: 57456 | O51: Terminated | P51: Needs Improvement | R51: =WEEKDAY(J52,2)=1 -> TRUE
B52: 00-17203266 | C52: Christine | D52: Cole | E52: Female | F52: New York | G52: New York City | H52: Bachelor | I52: 25607 | J52: 42674 | K52: N/A | L52: Marketing | M52: Marketing Manager | N52: 89713 | O52: Terminated | P52: Satisfactory | R52: =WEEKDAY(J53,2)=1 -> TRUE
B53: 00-17303355 | C53: Amber | D53: Gonzalez | E53: Female | F53: New York | G53: Buffalo | H53: Bachelor | I53: 30869 | J53: 43213 | K53: N/A | L53: Sales | M53: Sales Specialist | N53: 54735 | O53: Terminated | P53: Satisfactory | R53: =WEEKDAY(J54,2)=1 -> TRUE
B54: 00-17467311 | C54: John | D54: Martinez | E54: Female | F54: Michigan | G54: Detroit | H54: High School | I54: 34712 | J54: 43640 | K54: 44464 | L54: Customer Service | M54: Help Desk Technician | N54: 84792 | O54: Terminated | P54: Excellent | R54: =WEEKDAY(J55,2)=1 -> TRUE
B55: 00-17653101 | C55: Amy | D55: Ortega | E55: Female | F55: New York | G55: Buffalo | H55: High School | I55: 28820 | J55: 45285 | K55: N/A | L55: Customer Service | M55: Help Desk Technician | N55: 78098 | O55: Terminated | P55: Good | R55: =WEEKDAY(J56,2)=1 -> TRUE
B56: 00-18311653 | C56: Timothy | D56: Robertson | E56: Female | F56: Michigan | G56: Grand Rapids | H56: PhD | I56: 22457 | J56: 44459 | K56: N/A | L56: Sales | M56: Sales Specialist | N56: 75297 | O56: Terminated | P56: Excellent | R56: =WEEKDAY(J57,2)=1 -> TRUE
B57: 00-18429833 | C57: Andrew | D57: Nguyen | E57: Female | F57: New York | G57: New York City | H57: High School | I57: 25659 | J57: 42681 | K57: N/A | L57: Customer Service | M57: Customer Service Representative | N57: 57377 | O57: Terminated | P57: Needs Improvement | R57: =WEEKDAY(J58,2)=1 -> TRUE
B58: 00-18545499 | C58: Jose | D58: Turner | E58: Female | F58: New York | G58: Rochester | H58: Bachelor | I58: 33396 | J58: 45047 | K58: N/A | L58: Marketing | M58: Marketing Coordinator | N58: 70710 | O58: Terminated | P58: Satisfactory | R58: =WEEKDAY(J59,2)=1 -> TRUE
B59: 00-18678230 | C59: Patricia | D59: Galvan | E59: Female | F59: Virginia | G59: Norfolk | H59: Bachelor | I59: 22222 | J59: 43661 | K59: N/A | L59: Customer Service | M59: Customer Service Representative | N59: 66151 | O59: Terminated | P59: Good | R59: =WEEKDAY(J60,2)=1 -> TRUE
B60: 00-18852788 | C60: Adam | D60: Webb | E60: Female | F60: New York | G60: Buffalo | H60: Bachelor | I60: 37824 | J60: 43087 | K60: N/A | L60: Finance | M60: Accounts Payable Specialist | N60: 54561 | O60: Terminated | P60: Excellent | R60: =WEEKDAY(J61,2)=1 -> TRUE
B61: 00-18949617 | C61: Andrea | D61: Thompson | E61: Female | F61: Michigan | G61: Detroit | H61: Master | I61: 28784 | J61: 42240 | K61: N/A | L61: Operations | M61: Operations Analyst | N61: 81909 | O61: Terminated | P61: Excellent | R61: =WEEKDAY(J62,2)=1 -> TRUE
B62: 00-19257341 | C62: Brittany | D62: Sanders | E62: Female | F62: Pennsylvania | G62: Allentown | H62: PhD | I62: 34294 | J62: 44193 | K62: N/A | L62: Sales | M62: Sales Specialist | N62: 72753 | O62: Terminated | P62: Satisfactory | R62: =WEEKDAY(J63,2)=1 -> TRUE
B63: 00-19289546 | C63: Colleen | D63: Skinner | E63: Female | F63: New York | G63: New York City | H63: Bachelor | I63: 29921 | J63: 43297 | K63: 43477 | L63: Operations | M63: Inventory Specialist | N63: 63169 | O63: Terminated | P63: Good | R63: =WEEKDAY(J64,2)=1 -> TRUE
B64: 00-19338403 | C64: Judy | D64: Wilson | E64: Female | F64: Pennsylvania | G64: Pittsburgh | H64: Bachelor | I64: 33246 | J64: 44144 | K64: N/A | L64: Operations | M64: Operations Analyst | N64: 75587 | O64: Terminated | P64: Good | R64: =WEEKDAY(J65,2)=1 -> TRUE
...

Sheet AVG SALARY,OVERALL% AVG
A1: ALL Departments | C1: =COUNTA(STAFF!A:A) -> 8951 | E1: =AVERAGE(STAFF!M:M) -> 70964.214 | J1: =MAX(STAFF!M:M) -> 149377
A4: Deparments | C4: Head Count | E4: AVG Salary | G4: % Diff from overall avg | J4: Highest Salary
A5: Customer Service | C5: =COUNTIFS(STAFF!K1:K19000,A5) -> 1673 | E5: =AVERAGEIFS(STAFF!M:M,STAFF!K:K,A5) -> 65837.729 | G5: =E5-$E$1 -> -5126.4849 | J5: =_xlfn.MAXIFS(STAFF!M:M,STAFF!K:K,A5) -> 104359
A6: Operations | C6: =COUNTIFS(STAFF!K2:K19001,A6) -> 2718 | E6: =AVERAGEIFS(STAFF!M:M,STAFF!K:K,A6) -> 65400.25 | G6: =E6-$E$1 -> -5563.9633 | J6: =_xlfn.MAXIFS(STAFF!M:M,STAFF!K:K,A6) -> 115534
A7: Finance | C7: =COUNTIFS(STAFF!K3:K19002,A7) -> 452 | E7: =AVERAGEIFS(STAFF!M:M,STAFF!K:K,A7) -> 76451.144 | G7: =E7-$E$1 -> 5486.9303 | J7: =_xlfn.MAXIFS(STAFF!M:M,STAFF!K:K,A7) -> 149377
A8: Sales | C8: =COUNTIFS(STAFF!K4:K19003,A8) -> 1835 | E8: =AVERAGEIFS(STAFF!M:M,STAFF!K:K,A8) -> 76204.948 | G8: =E8-$E$1 -> 5240.7342 | J8: =_xlfn.MAXIFS(STAFF!M:M,STAFF!K:K,A8) -> 135055
A9: Marketing | C9: =COUNTIFS(STAFF!K5:K19004,A9) -> 718 | E9: =AVERAGEIFS(STAFF!M:M,STAFF!K:K,A9) -> 67659.024 | G9: =E9-$E$1 -> -3305.1898 | J9: =_xlfn.MAXIFS(STAFF!M:M,STAFF!K:K,A9) -> 110729
A10: HR | C10: =COUNTIFS(STAFF!K6:K19005,A10) -> 172 | E10: =AVERAGEIFS(STAFF!M:M,STAFF!K:K,A10) -> 64145.035 | G10: =E10-$E$1 -> -6819.1786 | J10: =_xlfn.MAXIFS(STAFF!M:M,STAFF!K:K,A10) -> 82203
A11: IT | C11: =COUNTIFS(STAFF!K7:K19006,A11) -> 1382 | E11: =AVERAGEIFS(STAFF!M:M,STAFF!K:K,A11) -> 81925.608 | G11: =E11-$E$1 -> 10961.394 | J11: =_xlfn.MAXIFS(STAFF!M:M,STAFF!K:K,A11) -> 133425

Sheet PIE CHART GENDER (DEPT)
A3: Row Labels | B3: Count of Employee_ID
A4: Customer Service | B4: 779
A5: Finance | B5: 210
A6: HR | B6: 94
A7: IT | B7: 601
A8: Marketing | B8: 352
A9: Operations | B9: 1250
A10: Sales | B10: 863
A11: Grand Total | B11: 4149

Sheet WORKFORCE SPREAD BY POSITION
A3: Row Labels | B3: Count of Atrrition status
A4: Accountant | B4: 173
A5: Accounts Payable Specialist | B5: 109
A6: Content Creator | B6: 308
A7: Customer Service Manager | B7: 74
A8: Customer Service Representative | B8: 503
A9: Finance Manager | B9: 9
A10: Financial Analyst | B10: 161
A11: Help Desk Technician | B11: 488
A12: HR Assistant | B12: 30
A13: HR Coordinator | B13: 56
A14: HR Manager | B14: 1
A15: Inventory Specialist | B15: 1044
... A32: Grand Total | B32: 8950

Sheet EMPLOYEE COUNT  BY SALARY
A3: Row Labels | B3: Count of Employee_ID | C3: Sum of Salary
A4: Customer Service | B4: 1673 | C4: 110146520
A5: Finance | B5: 452 | C5: 34555917
A6: HR | B6: 172 | C6: 11032946
A7: IT | B7: 1382 | C7: 113221190
A8: Marketing | B8: 718 | C8: 48579179
A9: Operations | B9: 2718 | C9: 177757880
A10: Sales | B10: 1835 | C10: 139836079
A11: Grand Total | B11: 8950 | C11: 635129711

Sheet MONTHLY TREND LINE
A3: Row Labels | B3: Count of Employee_ID
A4: Jan | B4: 734
A5: Feb | B5: 774
A6: Mar | B6: 761
A7: Apr | B7: 719
A8: May | B8: 755
A9: Jun | B9: 774
A10: Jul | B10: 747
A11: Aug | B11: 745
A12: Sep | B12: 753
A13: Oct | B13: 729
A14: Nov | B14: 734
A15: Dec | B15: 725
A16: Grand Total | B16: 8950

Sheet COUNT OF DEPT(PERFORMANCE)
A3: Department | B3: Count of Performance Rating
A4: Customer Service | B4: 779
A5: Finance | B5: 210
A6: HR | B6: 94
A7: IT | B7: 601
A8: Marketing | B8: 352
A9: Operations | B9: 1250
A10: Sales | B10: 863
A11: Grand Total | B11: 4149

Sheet TOP 10 EMPLOYEES
A1: Department | B1: (All)
A3: Row Labels | B3: Max of Salary
A4: Barbara | B4: 134173
A5: Gregory | B5: 132723
A6: Holly | B6: 133425
A7: Jose | B7: 141543
A8: Kristina | B8: 149377
A9: Lisa | B9: 131830
A10: Michael | B10: 132590
A11: Michelle | B11: 135055
A12: Raymond | B12: 133044
A13: Vincent | B13: 133039
A14: Grand Total | B14: 149377

Sheet PERFORMANCE RATING 
F1: - Performance Rating Analysis:
A3: Count of Employee_ID | B3: Column Labels
A4: Row Labels | B4: Excellent | C4: Good | D4: Needs Improvement | E4: Satisfactory | F4: Grand Total
A5: Customer Service | B5: 228 | C5: 611 | D5: 329 | E5: 505 | F5: 1673
A6: Finance | B6: 96 | C6: 202 | D6: 39 | E6: 115 | F6: 452
A7: HR | B7: 30 | C7: 75 | D7: 23 | E7: 44 | F7: 172
A8: IT | B8: 261 | C8: 583 | D8: 158 | E8: 380 | F8: 1382
A9: Marketing | B9: 108 | C9: 275 | D9: 124 | E9: 211 | F9: 718
A10: Operations | B10: 409 | C10: 1198 | D10: 322 | E10: 789 | F10: 2718
A11: Sales | B11: 434 | C11: 819 | D11: 128 | E11: 454 | F11: 1835
A12: Grand Total | B12: 1566 | C12: 3763 | D12: 1123 | E12: 2498 | F12: 8950

Sheet EMPLOYEE EDUCATION SNAPSHOT
A3: Row Labels | B3: Average of Salary
A4: Bachelor | B4: 69921.571
A5: High School | B5: 62144.287
A6: Master | B6: 82675.957
A7: PhD | B7: 86033.197
A8: Grand Total | B8: 70964.214
